05/18 11:02:35 - OpenCompass - [4m[97mINFO[0m - Task [pangu/cmmlu-high_school_biology]
05/18 11:02:35 - OpenCompass - [4m[97mINFO[0m - Start inferencing [pangu/cmmlu-high_school_biology]
  0%|                                                                                          | 0/169 [00:00<?, ?it/s]100%|â–ˆâ–ˆâ–ˆâ–ˆâ–ˆâ–ˆâ–ˆâ–ˆâ–ˆâ–ˆâ–ˆâ–ˆâ–ˆâ–ˆâ–ˆâ–ˆâ–ˆâ–ˆâ–ˆâ–ˆâ–ˆâ–ˆâ–ˆâ–ˆâ–ˆâ–ˆâ–ˆâ–ˆâ–ˆâ–ˆâ–ˆâ–ˆâ–ˆâ–ˆâ–ˆâ–ˆâ–ˆâ–ˆâ–ˆâ–ˆâ–ˆâ–ˆâ–ˆâ–ˆâ–ˆâ–ˆâ–ˆâ–ˆâ–ˆâ–ˆâ–ˆâ–ˆâ–ˆâ–ˆâ–ˆâ–ˆâ–ˆâ–ˆâ–ˆâ–ˆâ–ˆâ–ˆâ–ˆâ–ˆâ–ˆâ–ˆâ–ˆâ–ˆâ–ˆâ–ˆâ–ˆâ–ˆâ–ˆâ–ˆâ–ˆâ–ˆâ–ˆâ–ˆâ–ˆâ–ˆâ–ˆâ–ˆâ–ˆâ–ˆâ–ˆâ–ˆâ–ˆâ–ˆ| 169/169 [00:00<?, ?it/s]
[2024-05-18 11:02:36,118] [opencompass.openicl.icl_inferencer.icl_gen_inferencer] [INFO] Starting inference process...
  0%|                                                                                          | 0/169 [00:00<?, ?it/s]  0%|                                                                                          | 0/169 [00:00<?, ?it/s]
Traceback (most recent call last):
  File "C:\Users\ShuttleChaser\anaconda3\envs\opencompass\lib\site-packages\urllib3\response.py", line 712, in _error_catcher
    yield
  File "C:\Users\ShuttleChaser\anaconda3\envs\opencompass\lib\site-packages\urllib3\response.py", line 812, in _raw_read
    data = self._fp_read(amt) if not fp_closed else b""
  File "C:\Users\ShuttleChaser\anaconda3\envs\opencompass\lib\site-packages\urllib3\response.py", line 797, in _fp_read
    return self._fp.read(amt) if amt is not None else self._fp.read()
  File "C:\Users\ShuttleChaser\anaconda3\envs\opencompass\lib\http\client.py", line 466, in read
    s = self.fp.read(amt)
  File "C:\Users\ShuttleChaser\anaconda3\envs\opencompass\lib\socket.py", line 705, in readinto
    return self._sock.recv_into(b)
ConnectionResetError: [WinError 10054] è¿œç¨‹ä¸»æœºå¼ºè¿«å…³é—­äº†ä¸€ä¸ªçŽ°æœ‰çš„è¿žæŽ¥ã€‚

The above exception was the direct cause of the following exception:

Traceback (most recent call last):
  File "C:\Users\ShuttleChaser\anaconda3\envs\opencompass\lib\site-packages\requests\models.py", line 816, in generate
    yield from self.raw.stream(chunk_size, decode_content=True)
  File "C:\Users\ShuttleChaser\anaconda3\envs\opencompass\lib\site-packages\urllib3\response.py", line 934, in stream
    data = self.read(amt=amt, decode_content=decode_content)
  File "C:\Users\ShuttleChaser\anaconda3\envs\opencompass\lib\site-packages\urllib3\response.py", line 877, in read
    data = self._raw_read(amt)
  File "C:\Users\ShuttleChaser\anaconda3\envs\opencompass\lib\site-packages\urllib3\response.py", line 811, in _raw_read
    with self._error_catcher():
  File "C:\Users\ShuttleChaser\anaconda3\envs\opencompass\lib\contextlib.py", line 153, in __exit__
    self.gen.throw(typ, value, traceback)
  File "C:\Users\ShuttleChaser\anaconda3\envs\opencompass\lib\site-packages\urllib3\response.py", line 729, in _error_catcher
    raise ProtocolError(f"Connection broken: {e!r}", e) from e
urllib3.exceptions.ProtocolError: ("Connection broken: ConnectionResetError(10054, 'è¿œç¨‹ä¸»æœºå¼ºè¿«å…³é—­äº†ä¸€ä¸ªçŽ°æœ‰çš„è¿žæŽ¥ã€‚', None, 10054, None)", ConnectionResetError(10054, 'è¿œç¨‹ä¸»æœºå¼ºè¿«å…³é—­äº†ä¸€ä¸ªçŽ°æœ‰çš„è¿žæŽ¥ã€‚', None, 10054, None))

During handling of the above exception, another exception occurred:

Traceback (most recent call last):
  File "C:\Users\ShuttleChaser\Documents\python_script\LLM\opencompass\opencompass\runners\local_api.py", line 122, in launch
    inferencer.run(inferencer, tokens)
  File "C:\Users\ShuttleChaser\Documents\python_script\LLM\opencompass\opencompass\runners\local_api.py", line 52, in monkey_run
    self._inference()
  File "C:\Users\ShuttleChaser\Documents\python_script\LLM\opencompass\opencompass\tasks\openicl_infer.py", line 140, in _inference
    inferencer.inference(retriever,
  File "C:\Users\ShuttleChaser\Documents\python_script\LLM\opencompass\opencompass\openicl\icl_inferencer\icl_gen_inferencer.py", line 146, in inference
    results = self.model.generate_from_template(
  File "C:\Users\ShuttleChaser\Documents\python_script\LLM\opencompass\opencompass\models\base.py", line 165, in generate_from_template
    return self.generate(inputs, max_out_len=max_out_len, **kwargs)
  File "C:\Users\ShuttleChaser\Documents\python_script\LLM\opencompass\opencompass\models\pangu_api_lgl.py", line 80, in generate
    result = self._generate(input_i, max_out_len)
  File "C:\Users\ShuttleChaser\Documents\python_script\LLM\opencompass\opencompass\models\pangu_api_lgl.py", line 174, in _generate
    response = requests.request(method="POST", url=self.url, data=payload_json, headers=headers, verify=False)
  File "C:\Users\ShuttleChaser\anaconda3\envs\opencompass\lib\site-packages\requests\api.py", line 59, in request
    return session.request(method=method, url=url, **kwargs)
  File "C:\Users\ShuttleChaser\anaconda3\envs\opencompass\lib\site-packages\requests\sessions.py", line 589, in request
    resp = self.send(prep, **send_kwargs)
  File "C:\Users\ShuttleChaser\anaconda3\envs\opencompass\lib\site-packages\requests\sessions.py", line 747, in send
    r.content
  File "C:\Users\ShuttleChaser\anaconda3\envs\opencompass\lib\site-packages\requests\models.py", line 899, in content
    self._content = b"".join(self.iter_content(CONTENT_CHUNK_SIZE)) or b""
  File "C:\Users\ShuttleChaser\anaconda3\envs\opencompass\lib\site-packages\requests\models.py", line 818, in generate
    raise ChunkedEncodingError(e)
requests.exceptions.ChunkedEncodingError: ("Connection broken: ConnectionResetError(10054, 'è¿œç¨‹ä¸»æœºå¼ºè¿«å…³é—­äº†ä¸€ä¸ªçŽ°æœ‰çš„è¿žæŽ¥ã€‚', None, 10054, None)", ConnectionResetError(10054, 'è¿œç¨‹ä¸»æœºå¼ºè¿«å…³é—­äº†ä¸€ä¸ªçŽ°æœ‰çš„è¿žæŽ¥ã€‚', None, 10054, None))
